Workbook

Sheet بيانات الآليات 
A1: vehicle_code | B1: licence_number | C1: vehicle_type_en | D1: vehicle_type_ar | E1: vehicle_model_en | F1: vehicle_model_ar | G1: vehicle_dept | H1: vehicle_state | I1: Notes
A2: 1225 | B2: 3122555 | C2: Backhoe Loader | D2: حفار | E2: Caterpillar 428F, 2018 | F2: كاتربيلر 428F، موديل 2018 | G2: قسم محافظة الوسطى | H2: تعمل
A3: 1222 | B3: 3122255 | C3: Backhoe Loader | D3: حفار | E3: Caterpillar 428F, 2018 | F3: كاتربيلر 428F، موديل 2018 | G3: قسم محافظة خانيونس | H3: تعمل
A4: 1174 | B4: 3117455 | C4: Backhoe Loader | D4: حفار | E4: Caterpillar 428F, 2018 | F4: كاتربيلر 428F، موديل 2018 | G4: قسم محافظة خانيونس | H4: مدمرة
A5: 1067 | B5: 3106755 | C5: Administration Dept. | D5: آلية حركة | E5: Hyundai H1, 2016 | F5: هيونداي H1، موديل 2016 | G5: قسم محافظة الوسطى | H5: تعمل
A6: 56 | B6: 3129055 | C6: Compactor | D6: ضاغطة نفايات | E6: Iveco ML180E28, 2022 | F6: إيفيكو ML180E28، موديل 2022 | G6: قسم محافظة خانيونس | H6: تعمل
A7: 57 | B7: 3129155 | C7: Compactor | D7: ضاغطة نفايات | E7: Iveco ML180E28, 2022 | F7: إيفيكو ML180E28، موديل 2022 | G7: قسم محافظة خانيونس | H7: لا تعمل
A8: 58 | B8: 3129255 | C8: Compactor | D8: ضاغطة نفايات | E8: Iveco ML180E28, 2022 | F8: إيفيكو ML180E28، موديل 2022 | G8: قسم محافظة خانيونس | H8: لا تعمل
A9: 1059 | B9: 3105955 | C9: Administration Dept. | D9: آلية حركة | E9: KIA Sportage, 2016 | F9: كيا سبورتاج، موديل 2016 | G9: قسم محافظة الوسطى | H9: مدمرة
A10: 1118 | B10: 3111855 | C10: Medical Waste Collection | D10: آلية جمع نفايات طبية | E10: Mercedes-Benz Sprinter, 2011 | F10: مرسيدس بنز سبرينتر، موديل 2011 | G10: قسم الطبية | H10: لا تعمل
A11: 1117 | B11: 3111755 | C11: Medical Waste Collection | D11: آلية جمع نفايات طبية | E11: Mercedes-Benz Sprinter, 2011 | F11: مرسيدس بنز سبرينتر، موديل 2011 | G11: قسم الطبية | H11: لا تعمل
A12: 1151 | B12: 3115155 | C12: Administration Dept. | D12: آلية حركة | E12: Mitsubishi L200, 2018 | F12: ميتسوبيشي L200، موديل 2018 | G12: قسم محافظة الوسطى | H12: تعمل
A13: 1152 | B13: 3115255 | C13: Administration Dept. | D13: آلية حركة | E13: Mitsubishi L200, 2018 | F13: ميتسوبيشي L200، موديل 2018 | G13: قسم محافظة خانيونس | H13: تعمل
... A17: 30 | B17: 3064855 | C17: Tipper Crane | D17: رافعة قلاب | E17: Renault DXI280, 2008 | F17: رينو DXI280 موديل 2008 | G17: قسم محافظة الوسطى | H17: لا تعمل
A18: 0021 | B18: 3002155 | C18: Administration Dept. | D18: آلية حركة | E18: Toyota Hilux, 2010 | F18: تويوتا هايلكس موديل 2010 | G18: قسم محافظة الوسطى | H18: لا تعمل
A19: 1187 | B19: 3118755 | C19: Administration Dept. | D19: آلية حركة | E19: Volkswagens T4, 1995 | F19: فولكس فاجن T4 موديل 1995 | G19: قسم محافظة خانيونس | H19: مدمرة
A20: 73 | B20: 3118955 | C20: Tipper Crane | D20: رافعة قلاب | E20: Volvo FL 619, 1995 | F20: فولفو FL 619 موديل 1995 | G20: قسم محافظة الوسطى | H20: لا تعمل
A21: 75 | B21: 3119055 | C21: Tipper Crane | D21: رافعة قلاب | E21: Volvo FL 619, 1995 | F21: فولفو FL 619 موديل 1995 | G21: قسم محافظة الوسطى | H21: تعمل
A22: 16 | B22: 3065055 | C22: Tipper Crane | D22: رافعة قلاب | E22: Volvo FL 619, 1995 | F22: فولفو FL 619 موديل 1995 | G22: قسم محافظة الوسطى | H22: لا تعمل
A23: 17 | B23: 3065155 | C23: Tipper Crane | D23: رافعة قلاب | E23: Volvo FL 619, 1995 | F23: فولفو FL 619 موديل 1995 | G23: قسم محافظة الوسطى | H23: لا تعمل
A24: 88 | B24: 3108855 | C24: Tipper Truck | D24: شاحنة قلاب | E24: Volvo FM 64R, 2018 | F24: فولفو FM 64R موديل 2018 | G24: قسم محافظة الوسطى | H24: تعمل
A25: 86 | B25: 3108655 | C25: Tipper Truck | D25: شاحنة قلاب | E25: Volvo FM 64R, 2018 | F25: فولفو FM 64R موديل 2018 | G25: قسم محافظة الوسطى | H25: تعمل
A26: 87 | B26: 3108755 | C26: Vacuum Jetter | D26: كاسحة مجاري | E26: Volvo FM 64R, 2018 | F26: فولفو FM 64R موديل 2018 | G26: قسم محافظة الوسطى | H26: تعمل
A27: 33 | B27: 3114355 | C27: Compactor | D27: ضاغطة نفايات | E27: Volvo-FM64R, 2016 | F27: فولفو-FM64R موديل 2016 | G27: قسم محافظة الوسطى | H27: تعمل
A28: 35 | B28: 3114655 | C28: Compactor | D28: ضاغطة نفايات | E28: Volvo-FM64R, 2016 | F28: فولفو-FM64R موديل 2016 | G28: قسم محافظة خانيونس | H28: تعمل
A29: 37 | B29: 3114555 | C29: Compactor | D29: ضاغطة نفايات | E29: Volvo-FM64R, 2016 | F29: فولفو-FM64R موديل 2016 | G29: قسم محافظة خانيونس | H29: لا تعمل
A30: 38 | B30: 3114155 | C30: Compactor | D30: ضاغطة نفايات | E30: Volvo-FM64R, 2016 | F30: فولفو-FM64R موديل 2016 | G30: قسم محافظة الوسطى | H30: تعمل
... A41: 1176 | B41: 3117655 | C41: SkidSteer Loader | D41: بوبكات | E41: SkidSteer Loader CAT 232D | F41: كاتربيلر 232D، موديل ٢٠١٨ | G41: قسم المكب | H41: مدمرة

Sheet بنود أعمال الصيانة
A1: # | B1: اسم البند | C1: Description | D1: UOM | E1: Qty | F1: Service Cost (US$)
A2: 1 | B2: إصلاحات محرك | C2: Engine Repairs
A3: 1.1 | B3: منظم ضغط العادم | C3: EPG | D3: NO | E3: 1 | F3: 100
A4: 1.2 | B4: مصحة سولار | C4: FUEL PUMP | D4: NO | E4: 1 | F4: 100
A5: 1.3 | B5: تيوم تشارجر | C5: Turbocharger | D5: NO | E5: 1 | F5: 100
A6: 1.4 | B6: استبدال بخاخ | C6: injector replacements | D6: set | E6: 1 | F6: 100
A7: 1.5 | B7: تنظيف أو تبديل فلتر العادم | C7: DPF cleaning/replacement | D7: NO | E7: 1 | F7: 50
A8: 1.6 | B8: فلتر سولار | C8: Fuel Filter | D8: NO | E8: 1 | F8: 20
A9: 1.7 | B9: فلتر ميابيش | C9: Air Dryer Filter | D9: NO | E9: 1 | F9: 20
A10: 1.8 | B10: فلتر هواء | C10: AIR Filter | D10: NO | E10: 1 | F10: 20
A11: 1.9 | B11: فلتر زيت أولي | C11: Primary Oil Filter | D11: NO | E11: 1 | F11: 20
A12: 1.10 | B12: فلتر زيت ثانوي | C12: Secondary Oil Filter | D12: NO | E12: 1 | F12: 20
A13: 1.11 | B13: فلتر مكيف | C13: A/C Filter | D13: NO | E13: 1 | F13: 20
A14: 1.12 | B14: فلتر هيدروليك | C14: Hydraulic Filter | D14: NO | E14: 1 | F14: 20
... A21: 1.19 | B21: انابيب توصيل داخلية | C21: Internal Connecting Pipes | D21: NO | E21: 1 | F21: 200
A22: 2 | B22: نظام التبريد | C22: Cooling System
A23: 2.1 | B23: اصلاح راديتر | C23: Radiater repair | D23: NO | E23: 1 | F23: 200
A24: 2.2 | B24: استبدال راديتر | C24: Radiater replacement | D24: NO | E24: 1 | F24: 100
A25: 2.3 | B25: تيرموستات | C25: thermostat replacement | D25: NO | E25: 1 | F25: 50
A26: 2.4 | B26: صيانة كلتش مروحة التبريد | C26: Cooling fan clutch service | D26: NO | E26: 1 | F26: 200
A27: 2.5 | B27: مضحة مبرد | C27: Coolant Pump/Radiator Water Pump | D27: NO | E27: 1 | F27: 200
A28: 2.6 | B28: استبدال خراطيم سائل التبريد | C28: Coolant hoses replacement | D28: NO | E28: 1 | F28: 100
A29: 3 | B29: ناقل الحركة ونظام الدفع | C29: Transmission & Drivetrain
A30: 3.1 | B30: اصلاح جير بكس | C30: Gearbox repairs | D30: NO | E30: 1 | F30: 500
A31: 3.2 | B31: استبدال كلتش | C31: clutch replacement | D31: NO | E31: 1 | F31: 200
A32: 3.3 | B32: التجديد دسك وكلتش | C32: clutch repaire | D32: NO | E32: 1 | F32: 300
A33: 3.4 | B33: طرمبة كلتش علوية | C33: Clutch Master Cylinder-uper clutch pump | D33: NO | E33: 1 | F33: 100
A34: 3.5 | B34: طرمبة كلتش سفلية | C34: Clutch Slave Cylinder-lower clutch pump | D34: NO | E34: 1 | F34: 100
A35: 3.4 | B35: صيانة عمود الكردان ووصلاته | C35: propeller shaft and U-joints service | D35: NO | E35: 1 | F35: 300
A36: 3.5 | B36: اصلاح الدفرنس أو علبة | C36: differential repairs | D36: NO | E36: 1 | F36: 300
A37: 3.6 | B37: صيانة علبة التروس المساعدة | C37: PTO repairs | D37: NO | E37: 1 | F37: 200
A38: 3.7 | B38: تلف الخبيزيكي (صمام التغيير) | C38: Transmission Control Valve | D38: NO | E38: 1 | F38: 100
A39: 3.8 | B39: جمال درایف شافت | C39: Universal Joint (U-Joint) for Driveshaft | D39: NO | E39: 1 | F39: 100
A40: 3.9 | B40: صليب عمود الشفط | C40: Propeller Shaft Carrier / Driveshaft Bearing Bracket | D40: NO | E40: 1 | F40: 200
A41: 4 | B41: نظام التعليق والتوجيه | C41: Suspension & Steering
A42: 4.1 | B42: استبدال يايات ورقية أو تغيير | C42: Leaf spring replacement | D42: NO | E42: 1 | F42: 50
A43: 4.2 | B43: استبدال جوزة | C43: bushing replacement | D43: NO | E43: 1 | F43: 100
A44: 4.3 | B44: تغيير رؤوس أذرع التوجيه | C44: tie rod ends | D44: NO | E44: 1 | F44: 100
A45: 4.4 | B45: إصلاح مضخة الباور | C45: steering pump repairs | D45: NO | E45: 1 | F45: 50
A46: 4.5 | B46: برغي عجل صمولة | C46: Wheel Bolt and Nut | D46: NO | E46: 1 | F46: 50
...

Sheet بنود أعمال الصيانة (معدل)
A1: term_num | B1: repair_type_ar | C1: repair_type_en | D1: repair_desc_ar | E1: repair_desc_en | F1: uom | G1: qty | H1: service_cost
A2: 1.1 | B2: إصلاحات محرك | C2: Engine Repairs | D2: منظم ضغط العادم | E2: EPG | F2: NO | G2: 1 | H2: 100
A3: 1.2 | B3: إصلاحات محرك | C3: Engine Repairs | D3: مصحة سولار | E3: FUEL PUMP | F3: NO | G3: 1 | H3: 100
A4: 1.3 | B4: إصلاحات محرك | C4: Engine Repairs | D4: تيوم تشارجر | E4: Turbocharger | F4: NO | G4: 1 | H4: 100
A5: 1.4 | B5: إصلاحات محرك | C5: Engine Repairs | D5: استبدال بخاخ | E5: injector replacements | F5: set | G5: 1 | H5: 100
A6: 1.5 | B6: إصلاحات محرك | C6: Engine Repairs | D6: تنظيف أو تبديل فلتر العادم | E6: DPF cleaning/replacement | F6: NO | G6: 1 | H6: 50
A7: 1.6 | B7: إصلاحات محرك | C7: Engine Repairs | D7: فلتر سولار | E7: Fuel Filter | F7: NO | G7: 1 | H7: 20
A8: 1.7 | B8: إصلاحات محرك | C8: Engine Repairs | D8: فلتر ميابيش | E8: Air Dryer Filter | F8: NO | G8: 1 | H8: 20
A9: 1.8 | B9: إصلاحات محرك | C9: Engine Repairs | D9: فلتر هواء | E9: AIR Filter | F9: NO | G9: 1 | H9: 20
A10: 1.9 | B10: إصلاحات محرك | C10: Engine Repairs | D10: فلتر زيت أولي | E10: Primary Oil Filter | F10: NO | G10: 1 | H10: 20
A11: 1.10 | B11: إصلاحات محرك | C11: Engine Repairs | D11: فلتر زيت ثانوي | E11: Secondary Oil Filter | F11: NO | G11: 1 | H11: 20
A12: 1.11 | B12: إصلاحات محرك | C12: Engine Repairs | D12: فلتر مكيف | E12: A/C Filter | F12: NO | G12: 1 | H12: 20
A13: 1.12 | B13: إصلاحات محرك | C13: Engine Repairs | D13: فلتر هيدروليك | E13: Hydraulic Filter | F13: NO | G13: 1 | H13: 20
... A79: 7.19 | B79: الأعمال الهيدروليكية | C79: HYDRULIC | D79: كبسة تلبيج هيدروليك 5/8 انش | E79: Hose Fitting Cap 5/8 Inch, [19,22,24,27,30,32,36] MM | F79: No | G79: 1 | H79: 30
A80: 7.20 | B80: الأعمال الهيدروليكية | C80: HYDRULIC | D80: صيانة وتبديل ختم (رام) الاسطوانة | E80: Hydraulic cylinder (ram) seal replacement and overhaul | G80: 1 | H80: 200
A81: 7.21 | B81: الأعمال الهيدروليكية | C81: HYDRULIC | D81: صيانة أو تبديل مضخة الهيدروليك و PTO | E81: Hydraulic pump and PTO servicing/replacement | G81: 1 | H81: 200
A82: 8.1 | B82: أعمال صيانة الإطارات | C82: Tires Repair | D82: بنشر سيارة أو جيب | E82: Car or Jeep Tire Repair | F82: NO | G82: 1 | H82: 10
A83: 8.2 | B83: أعمال صيانة الإطارات | C83: Tires Repair | D83: بنشر شاحنة | E83: Truck Tire Repair | F83: NO | G83: 1 | H83: 70
A84: 8.3 | B84: أعمال صيانة الإطارات | C84: Tires Repair | D84: بنشر صغير مع رقعة مقاس 10 | E84: Small Tire Repair with Patch Size 10 | F84: NO | G84: 1 | H84: 30
A85: 8.4 | B85: أعمال صيانة الإطارات | C85: Tires Repair | D85: بنشر صغير مع رقعة مقاس 12 | E85: Small Tire Repair with Patch Size 12 | F85: NO | G85: 1 | H85: 40
A86: 8.5 | B86: أعمال صيانة الإطارات | C86: Tires Repair | D86: بنشر صغير مع رقعة مقاس 14 | E86: Small Tire Repair with Patch Size 14 | F86: NO | G86: 1 | H86: 70
A87: 8.6 | B87: أعمال صيانة الإطارات | C87: Tires Repair | D87: بنشر كبير مع رقعة مقاس 10 | E87: Large Tire Repair with Patch Size 10 | F87: NO | G87: 1 | H87: 80
A88: 8.7 | B88: أعمال صيانة الإطارات | C88: Tires Repair | D88: بنشر كبير مع رقعة مقاس 12 | E88: Tire Repair with Patch Size 12 | F88: NO | G88: 1 | H88: 100
A89: 8.8 | B89: أعمال صيانة الإطارات | C89: Tires Repair | D89: بنشر كبير مع رقعة مقاس 14 | E89: Large Tire Repair with Patch Size 14 | F89: NO | G89: 1 | H89: 120
A90: 8.9 | B90: أعمال صيانة الإطارات | C90: Tires Repair | D90: بلف نحاس تيوبلس | E90: Tubeless Copper Valve | F90: NO | G90: 1 | H90: 60
A91: 8.10 | B91: أعمال صيانة الإطارات | C91: Tires Repair | D91: بلف جلد سيارة او جيب | E91: Car or Jeep Rubber Valve | F91: NO | G91: 1 | H91: 10
A92: 8.11 | B92: أعمال صيانة الإطارات | C92: Tires Repair | D92: لحام كاوتشوك شاحنة | E92: Truck Tire Vulcanizing | F92: NO | G92: 1 | H92: 500
A93: 8.12 | B93: أعمال صيانة الإطارات | C93: Tires Repair | D93: لحام كاوتشوك سيارة أو جيب | E93: Car or Jeep Tire Vulcanizing | F93: NO | G93: 1 | H93: 300
... A117: 11.14 | B117: أعمال حدادة لجسم الآلية | C117: Chassis & Body | D117: اصلاح قواعد صناديق الأدوات | E117: Toolbox or fuel/air tank mount repairs | F117: NO | G117: 1 | H117: 500

Sheet سجل الصيانة
A1: log_date | B1: order_num | C1: vehicle_code | D1: vehicle_type_en | E1: vehicle_type_ar | F1: licence_number | G1: vehicle_model_ar | H1: vehicle_model_en | I1: term_num | J1: repair_desc_ar | K1: repair_desc_en | L1: statement | M1: unit | N1: qty | O1: unit_cost | P1: إجمالي السعر | Q1: repair_cost | R1: total_cost | S1: notes
A2: 46000 | B2: 01 | C2: 35 | D2: =_xlfn.IFNA(VLOOKUP(C2,'بيانات الآليات '!A:G,3,FALSE()),"") -> Compactor | E2: =_xlfn.IFNA(VLOOKUP(C2,'بيانات الآليات '!A:G,4,FALSE()),"") -> ضاغطة نفايات | F2: =_xlfn.IFNA(VLOOKUP(C2,'بيانات الآليات '!A:G,2,FALSE()),"") -> 3114655 | G2: =_xlfn.IFNA(VLOOKUP(C2,'بيانات الآليات '!A:G,6,FALSE()),"") -> فولفو-FM64R موديل 2016 | H2: =_xlfn.IFNA(VLOOKUP(C2,'بيانات الآليات '!A:G,5,FALSE()),"") -> Volvo-FM64R, 2016 | I2: 9.2 | J2: =_xlfn.IFNA(VLOOKUP(I2,Table14543[],2,FALSE()),"") -> زيت هيدروليك | K2: =_xlfn.IFNA(VLOOKUP(I2,Table14543[],3,FALSE()),"") -> ISO 68 | L2: =CONCATENATE("",I2,""," ",J2," ",K2) -> 9.2 زيت هيدروليك ISO 68 | M2: لتر | N2: 100 | O2: 15 | P2: =N2*O2 -> 1500 | Q2: 500 | R2: =(O2*N2)+Q2 -> 2000
A3: 46000 | B3: 01 | C3: 35 | D3: =_xlfn.IFNA(VLOOKUP(C3,'بيانات الآليات '!A:G,3,FALSE()),"") -> Compactor | E3: =_xlfn.IFNA(VLOOKUP(C3,'بيانات الآليات '!A:G,4,FALSE()),"") -> ضاغطة نفايات | F3: =_xlfn.IFNA(VLOOKUP(C3,'بيانات الآليات '!A:G,2,FALSE()),"") -> 3114655 | G3: =_xlfn.IFNA(VLOOKUP(C3,'بيانات الآليات '!A:G,6,FALSE()),"") -> فولفو-FM64R موديل 2016 | H3: =_xlfn.IFNA(VLOOKUP(C3,'بيانات الآليات '!A:G,5,FALSE()),"") -> Volvo-FM64R, 2016 | I3: 6.7 | J3: =_xlfn.IFNA(VLOOKUP(I3,Table14543[],2,FALSE()),"") -> استبدال أنظمة الإضاءة | K3: =_xlfn.IFNA(VLOOKUP(I3,Table14543[],3,FALSE()),"") -> replacement of lighting systems | L3: =CONCATENATE("",I3,""," ",J3," ",K3) -> 6.7 استبدال أنظمة الإضاءة replacement of lighting systems | M3: عدد | N3: 1 | P3: =N3*O3 -> 0 | Q3: 300 | R3: =(O3*N3)+Q3 -> 300
A4: 46000 | B4: 01 | C4: 35 | D4: =_xlfn.IFNA(VLOOKUP(C4,'بيانات الآليات '!A:G,3,FALSE()),"") -> Compactor | E4: =_xlfn.IFNA(VLOOKUP(C4,'بيانات الآليات '!A:G,4,FALSE()),"") -> ضاغطة نفايات | F4: =_xlfn.IFNA(VLOOKUP(C4,'بيانات الآليات '!A:G,2,FALSE()),"") -> 3114655 | G4: =_xlfn.IFNA(VLOOKUP(C4,'بيانات الآليات '!A:G,6,FALSE()),"") -> فولفو-FM64R موديل 2016 | H4: =_xlfn.IFNA(VLOOKUP(C4,'بيانات الآليات '!A:G,5,FALSE()),"") -> Volvo-FM64R, 2016 | I4: 6.9 | J4: =_xlfn.IFNA(VLOOKUP(I4,Table14543[],2,FALSE()),"") -> اصلاح لوحة كهربائية | K4: =_xlfn.IFNA(VLOOKUP(I4,Table14543[],3,FALSE()),"") -> control modules repair | L4: =CONCATENATE("",I4,""," ",J4," ",K4) -> 6.9 اصلاح لوحة كهربائية control modules repair | M4: عدد | N4: 1 | P4: =N4*O4 -> 0 | Q4: 100 | R4: =(O4*N4)+Q4 -> 100
A5: 46000 | B5: 01 | C5: 35 | D5: =_xlfn.IFNA(VLOOKUP(C5,'بيانات الآليات '!A:G,3,FALSE()),"") -> Compactor | E5: =_xlfn.IFNA(VLOOKUP(C5,'بيانات الآليات '!A:G,4,FALSE()),"") -> ضاغطة نفايات | F5: =_xlfn.IFNA(VLOOKUP(C5,'بيانات الآليات '!A:G,2,FALSE()),"") -> 3114655 | G5: =_xlfn.IFNA(VLOOKUP(C5,'بيانات الآليات '!A:G,6,FALSE()),"") -> فولفو-FM64R موديل 2016 | H5: =_xlfn.IFNA(VLOOKUP(C5,'بيانات الآليات '!A:G,5,FALSE()),"") -> Volvo-FM64R, 2016 | I5: 9.1 | J5: =_xlfn.IFNA(VLOOKUP(I5,Table14543[],2,FALSE()),"") -> زيت محرك بكر | K5: =_xlfn.IFNA(VLOOKUP(I5,Table14543[],3,FALSE()),"") -> SAE 15W 40 API-Ci4-85102464 | L5: =CONCATENATE("",I5,""," ",J5," ",K5) -> 9.1 زيت محرك بكر SAE 15W 40 API-Ci4-85102464 | M5: لتر | N5: 30 | O5: 15 | P5: =#REF!*O5 -> #REF! | Q5: 150 | R5: =(O5*N5)+Q5 -> 600
A6: 46000 | B6: 01 | C6: 35 | D6: =_xlfn.IFNA(VLOOKUP(C6,'بيانات الآليات '!A:G,3,FALSE()),"") -> Compactor | E6: =_xlfn.IFNA(VLOOKUP(C6,'بيانات الآليات '!A:G,4,FALSE()),"") -> ضاغطة نفايات | F6: =_xlfn.IFNA(VLOOKUP(C6,'بيانات الآليات '!A:G,2,FALSE()),"") -> 3114655 | G6: =_xlfn.IFNA(VLOOKUP(C6,'بيانات الآليات '!A:G,6,FALSE()),"") -> فولفو-FM64R موديل 2016 | H6: =_xlfn.IFNA(VLOOKUP(C6,'بيانات الآليات '!A:G,5,FALSE()),"") -> Volvo-FM64R, 2016 | I6: 1.7 | J6: =_xlfn.IFNA(VLOOKUP(I6,Table14543[],2,FALSE()),"") -> فلتر ميابيش | K6: =_xlfn.IFNA(VLOOKUP(I6,Table14543[],3,FALSE()),"") -> Air Dryer Filter | L6: =CONCATENATE("",I6,""," ",J6," ",K6) -> 1.7 فلتر ميابيش Air Dryer Filter | M6: عدد | N6: 1 | O6: 400 | P6: =N6*O6 -> 400 | Q6: 20 | R6: =(O6*N6)+Q6 -> 420
A7: 46000 | B7: 01 | C7: 35 | D7: =_xlfn.IFNA(VLOOKUP(C7,'بيانات الآليات '!A:G,3,FALSE()),"") -> Compactor | E7: =_xlfn.IFNA(VLOOKUP(C7,'بيانات الآليات '!A:G,4,FALSE()),"") -> ضاغطة نفايات | F7: =_xlfn.IFNA(VLOOKUP(C7,'بيانات الآليات '!A:G,2,FALSE()),"") -> 3114655 | G7: =_xlfn.IFNA(VLOOKUP(C7,'بيانات الآليات '!A:G,6,FALSE()),"") -> فولفو-FM64R موديل 2016 | H7: =_xlfn.IFNA(VLOOKUP(C7,'بيانات الآليات '!A:G,5,FALSE()),"") -> Volvo-FM64R, 2016 | I7: 1.8 | J7: =_xlfn.IFNA(VLOOKUP(I7,Table14543[],2,FALSE()),"") -> فلتر هواء | K7: =_xlfn.IFNA(VLOOKUP(I7,Table14543[],3,FALSE()),"") -> AIR Filter | L7: =CONCATENATE("",I7,""," ",J7," ",K7) -> 1.8 فلتر هواء AIR Filter | M7: عدد | N7: 1 | O7: 600 | P7: =N7*O7 -> 600 | Q7: 20 | R7: =(O7*N7)+Q7 -> 620
A8: 46000 | B8: 01 | C8: 56 | D8: =_xlfn.IFNA(VLOOKUP(C8,'بيانات الآليات '!A:G,3,FALSE()),"") -> Compactor | E8: =_xlfn.IFNA(VLOOKUP(C8,'بيانات الآليات '!A:G,4,FALSE()),"") -> ضاغطة نفايات | F8: =_xlfn.IFNA(VLOOKUP(C8,'بيانات الآليات '!A:G,2,FALSE()),"") -> 3129055 | G8: =_xlfn.IFNA(VLOOKUP(C8,'بيانات الآليات '!A:G,6,FALSE()),"") -> إيفيكو ML180E28، موديل 2022 | H8: =_xlfn.IFNA(VLOOKUP(C8,'بيانات الآليات '!A:G,5,FALSE()),"") -> Iveco ML180E28, 2022 | I8: 9.2 | J8: =_xlfn.IFNA(VLOOKUP(I8,Table14543[],2,FALSE()),"") -> زيت هيدروليك | K8: =_xlfn.IFNA(VLOOKUP(I8,Table14543[],3,FALSE()),"") -> ISO 68 | L8: =CONCATENATE("",I8,""," ",J8," ",K8) -> 9.2 زيت هيدروليك ISO 68 | M8: لتر | N8: 80 | O8: 15 | P8: =N8*O8 -> 1200 | Q8: 400 | R8: =(O8*N8)+Q8 -> 1600
A9: 46000 | B9: 01 | C9: 56 | D9: =_xlfn.IFNA(VLOOKUP(C9,'بيانات الآليات '!A:G,3,FALSE()),"") -> Compactor | E9: =_xlfn.IFNA(VLOOKUP(C9,'بيانات الآليات '!A:G,4,FALSE()),"") -> ضاغطة نفايات | F9: =_xlfn.IFNA(VLOOKUP(C9,'بيانات الآليات '!A:G,2,FALSE()),"") -> 3129055 | G9: =_xlfn.IFNA(VLOOKUP(C9,'بيانات الآليات '!A:G,6,FALSE()),"") -> إيفيكو ML180E28، موديل 2022 | H9: =_xlfn.IFNA(VLOOKUP(C9,'بيانات الآليات '!A:G,5,FALSE()),"") -> Iveco ML180E28, 2022 | I9: 6.7 | J9: =_xlfn.IFNA(VLOOKUP(I9,Table14543[],2,FALSE()),"") -> استبدال أنظمة الإضاءة | K9: =_xlfn.IFNA(VLOOKUP(I9,Table14543[],3,FALSE()),"") -> replacement of lighting systems | L9: =CONCATENATE("",I9,""," ",J9," ",K9) -> 6.7 استبدال أنظمة الإضاءة replacement of lighting systems | M9: عدد | N9: 1 | P9: =N9*O9 -> 0 | Q9: 300 | R9: =(O9*N9)+Q9 -> 300
A10: 46000 | B10: 01 | C10: 56 | D10: =_xlfn.IFNA(VLOOKUP(C10,'بيانات الآليات '!A:G,3,FALSE()),"") -> Compactor | E10: =_xlfn.IFNA(VLOOKUP(C10,'بيانات الآليات '!A:G,4,FALSE()),"") -> ضاغطة نفايات | F10: =_xlfn.IFNA(VLOOKUP(C10,'بيانات الآليات '!A:G,2,FALSE()),"") -> 3129055 | G10: =_xlfn.IFNA(VLOOKUP(C10,'بيانات الآليات '!A:G,6,FALSE()),"") -> إيفيكو ML180E28، موديل 2022 | H10: =_xlfn.IFNA(VLOOKUP(C10,'بيانات الآليات '!A:G,5,FALSE()),"") -> Iveco ML180E28, 2022 | I10: 11.9 | J10: =_xlfn.IFNA(VLOOKUP(I10,Table14543[],2,FALSE()),"") -> إعادة لحام دعامات الأبواب الخلفية أو الجانبية | K10: =_xlfn.IFNA(VLOOKUP(I10,Table14543[],3,FALSE()),"") -> Re-welding tailgate or side door supports | L10: =CONCATENATE("",I10,""," ",J10," ",K10) -> 11.9 إعادة لحام دعامات الأبواب الخلفية أو الجانبية Re-welding tailgate or side door supports | M10: عدد | N10: 1 | P10: =N10*O10 -> 0 | Q10: 100 | R10: =(O10*N10)+Q10 -> 100
A11: 46000 | B11: 01 | C11: 56 | D11: =_xlfn.IFNA(VLOOKUP(C11,'بيانات الآليات '!A:G,3,FALSE()),"") -> Compactor | E11: =_xlfn.IFNA(VLOOKUP(C11,'بيانات الآليات '!A:G,4,FALSE()),"") -> ضاغطة نفايات | F11: =_xlfn.IFNA(VLOOKUP(C11,'بيانات الآليات '!A:G,2,FALSE()),"") -> 3129055 | G11: =_xlfn.IFNA(VLOOKUP(C11,'بيانات الآليات '!A:G,6,FALSE()),"") -> إيفيكو ML180E28، موديل 2022 | H11: =_xlfn.IFNA(VLOOKUP(C11,'بيانات الآليات '!A:G,5,FALSE()),"") -> Iveco ML180E28, 2022 | I11: 9.1 | J11: =_xlfn.IFNA(VLOOKUP(I11,Table14543[],2,FALSE()),"") -> زيت محرك بكر | K11: =_xlfn.IFNA(VLOOKUP(I11,Table14543[],3,FALSE()),"") -> SAE 15W 40 API-Ci4-85102464 | L11: =CONCATENATE("",I11,""," ",J11," ",K11) -> 9.1 زيت محرك بكر SAE 15W 40 API-Ci4-85102464 | M11: لتر | N11: 15 | O11: 15 | P11: =N11*O11 -> 225 | Q11: 75 | R11: =(O11*N11)+Q11 -> 300
A12: 46000 | B12: 01 | C12: 56 | D12: =_xlfn.IFNA(VLOOKUP(C12,'بيانات الآليات '!A:G,3,FALSE()),"") -> Compactor | E12: =_xlfn.IFNA(VLOOKUP(C12,'بيانات الآليات '!A:G,4,FALSE()),"") -> ضاغطة نفايات | F12: =_xlfn.IFNA(VLOOKUP(C12,'بيانات الآليات '!A:G,2,FALSE()),"") -> 3129055 | G12: =_xlfn.IFNA(VLOOKUP(C12,'بيانات الآليات '!A:G,6,FALSE()),"") -> إيفيكو ML180E28، موديل 2022 | H12: =_xlfn.IFNA(VLOOKUP(C12,'بيانات الآليات '!A:G,5,FALSE()),"") -> Iveco ML180E28, 2022 | I12: 1.8 | J12: =_xlfn.IFNA(VLOOKUP(I12,Table14543[],2,FALSE()),"") -> فلتر هواء | K12: =_xlfn.IFNA(VLOOKUP(I12,Table14543[],3,FALSE()),"") -> AIR Filter | L12: =CONCATENATE("",I12,""," ",J12," ",K12) -> 1.8 فلتر هواء AIR Filter | M12: عدد | N12: 1 | O12: 450 | P12: =N12*O12 -> 450 | Q12: 20 | R12: =(O12*N12)+Q12 -> 470
A13: 46000 | B13: 01 | C13: 400 | D13: =_xlfn.IFNA(VLOOKUP(C13,'بيانات الآليات '!A:G,3,FALSE()),"") -> Roll on/off | E13: =_xlfn.IFNA(VLOOKUP(C13,'بيانات الآليات '!A:G,4,FALSE()),"") -> رمثة - شاحنة كبيرة | F13: =_xlfn.IFNA(VLOOKUP(C13,'بيانات الآليات '!A:G,2,FALSE()),"") -> 3113855 | G13: =_xlfn.IFNA(VLOOKUP(C13,'بيانات الآليات '!A:G,6,FALSE()),"") -> فولفو FM84FR، موديل ٢٠١٦ | H13: =_xlfn.IFNA(VLOOKUP(C13,'بيانات الآليات '!A:G,5,FALSE()),"") -> Volvo-FM84FR, 2016 | I13: 9.2 | J13: =_xlfn.IFNA(VLOOKUP(I13,Table14543[],2,FALSE()),"") -> زيت هيدروليك | K13: =_xlfn.IFNA(VLOOKUP(I13,Table14543[],3,FALSE()),"") -> ISO 68 | L13: =CONCATENATE("",I13,""," ",J13," ",K13) -> 9.2 زيت هيدروليك ISO 68 | M13: لتر | N13: 50 | O13: 15 | P13: =N13*O13 -> 750 | Q13: 250 | R13: =(O13*N13)+Q13 -> 1000
A14: 46000 | B14: 01 | C14: 400 | D14: =_xlfn.IFNA(VLOOKUP(C14,'بيانات الآليات '!A:G,3,FALSE()),"") -> Roll on/off | E14: =_xlfn.IFNA(VLOOKUP(C14,'بيانات الآليات '!A:G,4,FALSE()),"") -> رمثة - شاحنة كبيرة | F14: =_xlfn.IFNA(VLOOKUP(C14,'بيانات الآليات '!A:G,2,FALSE()),"") -> 3113855 | G14: =_xlfn.IFNA(VLOOKUP(C14,'بيانات الآليات '!A:G,6,FALSE()),"") -> فولفو FM84FR، موديل ٢٠١٦ | H14: =_xlfn.IFNA(VLOOKUP(C14,'بيانات الآليات '!A:G,5,FALSE()),"") -> Volvo-FM84FR, 2016 | I14: 6.7 | J14: =_xlfn.IFNA(VLOOKUP(I14,Table14543[],2,FALSE()),"") -> استبدال أنظمة الإضاءة | K14: =_xlfn.IFNA(VLOOKUP(I14,Table14543[],3,FALSE()),"") -> replacement of lighting systems | L14: =CONCATENATE("",I14,""," ",J14," ",K14) -> 6.7 استبدال أنظمة الإضاءة replacement of lighting systems | M14: عدد | N14: 1 | P14: =N14*O14 -> 0 | Q14: 300 | R14: =(O14*N14)+Q14 -> 300
A15: 46000 | B15: 01 | C15: 400 | D15: =_xlfn.IFNA(VLOOKUP(C15,'بيانات الآليات '!A:G,3,FALSE()),"") -> Roll on/off | E15: =_xlfn.IFNA(VLOOKUP(C15,'بيانات الآليات '!A:G,4,FALSE()),"") -> رمثة - شاحنة كبيرة | F15: =_xlfn.IFNA(VLOOKUP(C15,'بيانات الآليات '!A:G,2,FALSE()),"") -> 3113855 | G15: =_xlfn.IFNA(VLOOKUP(C15,'بيانات الآليات '!A:G,6,FALSE()),"") -> فولفو FM84FR، موديل ٢٠١٦ | H15: =_xlfn.IFNA(VLOOKUP(C15,'بيانات الآليات '!A:G,5,FALSE()),"") -> Volvo-FM84FR, 2016 | I15: 1.7 | J15: =_xlfn.IFNA(VLOOKUP(I15,Table14543[],2,FALSE()),"") -> فلتر ميابيش | K15: =_xlfn.IFNA(VLOOKUP(I15,Table14543[],3,FALSE()),"") -> Air Dryer Filter | L15: =CONCATENATE("",I15,""," ",J15," ",K15) -> 1.7 فلتر ميابيش Air Dryer Filter | M15: عدد | N15: 1 | O15: 400 | P15: =N15*O15 -> 400 | Q15: 20 | R15: =(O15*N15)+Q15 -> 420
A16: 46000 | B16: 01 | C16: 400 | D16: =_xlfn.IFNA(VLOOKUP(C16,'بيانات الآليات '!A:G,3,FALSE()),"") -> Roll on/off | E16: =_xlfn.IFNA(VLOOKUP(C16,'بيانات الآليات '!A:G,4,FALSE()),"") -> رمثة - شاحنة كبيرة | F16: =_xlfn.IFNA(VLOOKUP(C16,'بيانات الآليات '!A:G,2,FALSE()),"") -> 3113855 | G16: =_xlfn.IFNA(VLOOKUP(C16,'بيانات الآليات '!A:G,6,FALSE()),"") -> فولفو FM84FR، موديل ٢٠١٦ | H16: =_xlfn.IFNA(VLOOKUP(C16,'بيانات الآليات '!A:G,5,FALSE()),"") -> Volvo-FM84FR, 2016 | I16: 9.1 | J16: =_xlfn.IFNA(VLOOKUP(I16,Table14543[],2,FALSE()),"") -> زيت محرك بكر | K16: =_xlfn.IFNA(VLOOKUP(I16,Table14543[],3,FALSE()),"") -> SAE 15W 40 API-Ci4-85102464 | L16: =CONCATENATE("",I16,""," ",J16," ",K16) -> 9.1 زيت محرك بكر SAE 15W 40 API-Ci4-85102464 | M16: لتر | N16: 30 | O16: 15 | P16: =N16*O16 -> 450 | Q16: 150 | R16: =(O16*N16)+Q16 -> 600
A17: 46000 | B17: 01 | C17: 400 | D17: =_xlfn.IFNA(VLOOKUP(C17,'بيانات الآليات '!A:G,3,FALSE()),"") -> Roll on/off | E17: =_xlfn.IFNA(VLOOKUP(C17,'بيانات الآليات '!A:G,4,FALSE()),"") -> رمثة - شاحنة كبيرة | F17: =_xlfn.IFNA(VLOOKUP(C17,'بيانات الآليات '!A:G,2,FALSE()),"") -> 3113855 | G17: =_xlfn.IFNA(VLOOKUP(C17,'بيانات الآليات '!A:G,6,FALSE()),"") -> فولفو FM84FR، موديل ٢٠١٦ | H17: =_xlfn.IFNA(VLOOKUP(C17,'بيانات الآليات '!A:G,5,FALSE()),"") -> Volvo-FM84FR, 2016 | I17: 1.8 | J17: =_xlfn.IFNA(VLOOKUP(I17,Table14543[],2,FALSE()),"") -> فلتر هواء | K17: =_xlfn.IFNA(VLOOKUP(I17,Table14543[],3,FALSE()),"") -> AIR Filter | L17: =CONCATENATE("",I17,""," ",J17," ",K17) -> 1.8 فلتر هواء AIR Filter | M17: عدد | N17: 1 | O17: 600 | P17: =N17*O17 -> 600 | Q17: 20 | R17: =(O17*N17)+Q17 -> 620
A18: 46002 | B18: 02 | C18: 16 | D18: =_xlfn.IFNA(VLOOKUP(C18,'بيانات الآليات '!A:G,3,FALSE()),"") -> Tipper Crane | E18: =_xlfn.IFNA(VLOOKUP(C18,'بيانات الآليات '!A:G,4,FALSE()),"") -> رافعة قلاب | F18: =_xlfn.IFNA(VLOOKUP(C18,'بيانات الآليات '!A:G,2,FALSE()),"") -> 3065055 | G18: =_xlfn.IFNA(VLOOKUP(C18,'بيانات الآليات '!A:G,6,FALSE()),"") -> فولفو FL 619 موديل 1995 | H18: =_xlfn.IFNA(VLOOKUP(C18,'بيانات الآليات '!A:G,5,FALSE()),"") -> Volvo FL 619, 1995 | I18: 9.1 | J18: =_xlfn.IFNA(VLOOKUP(I18,Table14543[],2,FALSE()),"") -> زيت محرك بكر | K18: =_xlfn.IFNA(VLOOKUP(I18,Table14543[],3,FALSE()),"") -> SAE 15W 40 API-Ci4-85102464 | L18: =CONCATENATE("",I18,""," ",J18," ",K18) -> 9.1 زيت محرك بكر SAE 15W 40 API-Ci4-85102464 | M18: عدد | P18: =N18*O18 -> 0 | R18: =(O18*N18)+Q18 -> 0
E19: =_xlfn.IFNA(VLOOKUP(C19,'بيانات الآليات '!A:G,4,FALSE()),"") | F19: =_xlfn.IFNA(VLOOKUP(C19,'بيانات الآليات '!A:G,2,FALSE()),"") | H19: =_xlfn.IFNA(VLOOKUP(C19,'بيانات الآليات '!A:G,5,FALSE()),"") | J19: =_xlfn.IFNA(VLOOKUP(I19,Table14543[],2,FALSE()),"") | K19: =_xlfn.IFNA(VLOOKUP(I19,Table14543[],3,FALSE()),"") | L19: =CONCATENATE("",I19,""," ",J19," ",K19) | P19: =N19*O19 -> 0 | R19: =(O19*N19)+Q19 -> 0
E20: =_xlfn.IFNA(VLOOKUP(C20,'بيانات الآليات '!A:G,4,FALSE()),"") | F20: =_xlfn.IFNA(VLOOKUP(C20,'بيانات الآليات '!A:G,2,FALSE()),"") | H20: =_xlfn.IFNA(VLOOKUP(C20,'بيانات الآليات '!A:G,5,FALSE()),"") | J20: =_xlfn.IFNA(VLOOKUP(I20,Table14543[],2,FALSE()),"") | K20: =_xlfn.IFNA(VLOOKUP(I20,Table14543[],3,FALSE()),"") | L20: =CONCATENATE("",I20,""," ",J20," ",K20) | P20: =N20*O20 -> 0 | R20: =(O20*N20)+Q20 -> 0
E21: =_xlfn.IFNA(VLOOKUP(C21,'بيانات الآليات '!A:G,4,FALSE()),"") | F21: =_xlfn.IFNA(VLOOKUP(C21,'بيانات الآليات '!A:G,2,FALSE()),"") | H21: =_xlfn.IFNA(VLOOKUP(C21,'بيانات الآليات '!A:G,5,FALSE()),"") | J21: =_xlfn.IFNA(VLOOKUP(I21,Table14543[],2,FALSE()),"") | K21: =_xlfn.IFNA(VLOOKUP(I21,Table14543[],3,FALSE()),"") | L21: =CONCATENATE("",I21,""," ",J21," ",K21) | P21: =N21*O21 -> 0 | R21: =(O21*N21)+Q21 -> 0
E22: =_xlfn.IFNA(VLOOKUP(C22,'بيانات الآليات '!A:G,4,FALSE()),"") | F22: =_xlfn.IFNA(VLOOKUP(C22,'بيانات الآليات '!A:G,2,FALSE()),"") | H22: =_xlfn.IFNA(VLOOKUP(C22,'بيانات الآليات '!A:G,5,FALSE()),"") | J22: =_xlfn.IFNA(VLOOKUP(I22,Table14543[],2,FALSE()),"") | K22: =_xlfn.IFNA(VLOOKUP(I22,Table14543[],3,FALSE()),"") | L22: =CONCATENATE("",I22,""," ",J22," ",K22) | P22: =N22*O22 -> 0 | R22: =(O22*N22)+Q22 -> 0
E23: =_xlfn.IFNA(VLOOKUP(C23,'بيانات الآليات '!A:G,4,FALSE()),"") | F23: =_xlfn.IFNA(VLOOKUP(C23,'بيانات الآليات '!A:G,2,FALSE()),"") | H23: =_xlfn.IFNA(VLOOKUP(C23,'بيانات الآليات '!A:G,5,FALSE()),"") | J23: =_xlfn.IFNA(VLOOKUP(I23,Table14543[],2,FALSE()),"") | K23: =_xlfn.IFNA(VLOOKUP(I23,Table14543[],3,FALSE()),"") | L23: =CONCATENATE("",I23,""," ",J23," ",K23) | P23: =N23*O23 -> 0 | R23: =(O23*N23)+Q23 -> 0
E24: =_xlfn.IFNA(VLOOKUP(C24,'بيانات الآليات '!A:G,4,FALSE()),"") | F24: =_xlfn.IFNA(VLOOKUP(C24,'بيانات الآليات '!A:G,2,FALSE()),"") | H24: =_xlfn.IFNA(VLOOKUP(C24,'بيانات الآليات '!A:G,5,FALSE()),"") | J24: =_xlfn.IFNA(VLOOKUP(I24,Table14543[],2,FALSE()),"") | K24: =_xlfn.IFNA(VLOOKUP(I24,Table14543[],3,FALSE()),"") | L24: =CONCATENATE("",I24,""," ",J24," ",K24) | P24: =N24*O24 -> 0 | R24: =(O24*N24)+Q24 -> 0
E25: =_xlfn.IFNA(VLOOKUP(C25,'بيانات الآليات '!A:G,4,FALSE()),"") | F25: =_xlfn.IFNA(VLOOKUP(C25,'بيانات الآليات '!A:G,2,FALSE()),"") | H25: =_xlfn.IFNA(VLOOKUP(C25,'بيانات الآليات '!A:G,5,FALSE()),"") | J25: =_xlfn.IFNA(VLOOKUP(I25,Table14543[],2,FALSE()),"") | K25: =_xlfn.IFNA(VLOOKUP(I25,Table14543[],3,FALSE()),"") | L25: =CONCATENATE("",I25,""," ",J25," ",K25) | P25: =N25*O25 -> 0 | R25: =(O25*N25)+Q25 -> 0
E26: =_xlfn.IFNA(VLOOKUP(C26,'بيانات الآليات '!A:G,4,FALSE()),"") | F26: =_xlfn.IFNA(VLOOKUP(C26,'بيانات الآليات '!A:G,2,FALSE()),"") | H26: =_xlfn.IFNA(VLOOKUP(C26,'بيانات الآليات '!A:G,5,FALSE()),"") | J26: =_xlfn.IFNA(VLOOKUP(I26,Table14543[],2,FALSE()),"") | K26: =_xlfn.IFNA(VLOOKUP(I26,Table14543[],3,FALSE()),"") | L26: =CONCATENATE("",I26,""," ",J26," ",K26) | P26: =N26*O26 -> 0 | R26: =(O26*N26)+Q26 -> 0
E27: =_xlfn.IFNA(VLOOKUP(C27,'بيانات الآليات '!A:G,4,FALSE()),"") | F27: =_xlfn.IFNA(VLOOKUP(C27,'بيانات الآليات '!A:G,2,FALSE()),"") | H27: =_xlfn.IFNA(VLOOKUP(C27,'بيانات الآليات '!A:G,5,FALSE()),"") | J27: =_xlfn.IFNA(VLOOKUP(I27,Table14543[],2,FALSE()),"") | K27: =_xlfn.IFNA(VLOOKUP(I27,Table14543[],3,FALSE()),"") | L27: =CONCATENATE("",I27,""," ",J27," ",K27) | P27: =N27*O27 -> 0 | R27: =(O27*N27)+Q27 -> 0
E28: =_xlfn.IFNA(VLOOKUP(C28,'بيانات الآليات '!A:G,4,FALSE()),"") | F28: =_xlfn.IFNA(VLOOKUP(C28,'بيانات الآليات '!A:G,2,FALSE()),"") | H28: =_xlfn.IFNA(VLOOKUP(C28,'بيانات الآليات '!A:G,5,FALSE()),"") | J28: =_xlfn.IFNA(VLOOKUP(I28,Table14543[],2,FALSE()),"") | K28: =_xlfn.IFNA(VLOOKUP(I28,Table14543[],3,FALSE()),"") | L28: =CONCATENATE("",I28,""," ",J28," ",K28) | P28: =N28*O28 -> 0 | R28: =(O28*N28)+Q28 -> 0
E29: =_xlfn.IFNA(VLOOKUP(C29,'بيانات الآليات '!A:G,4,FALSE()),"") | F29: =_xlfn.IFNA(VLOOKUP(C29,'بيانات الآليات '!A:G,2,FALSE()),"") | H29: =_xlfn.IFNA(VLOOKUP(C29,'بيانات الآليات '!A:G,5,FALSE()),"") | J29: =_xlfn.IFNA(VLOOKUP(I29,Table14543[],2,FALSE()),"") | K29: =_xlfn.IFNA(VLOOKUP(I29,Table14543[],3,FALSE()),"") | L29: =CONCATENATE("",I29,""," ",J29," ",K29) | P29: =N29*O29 -> 0 | R29: =(O29*N29)+Q29 -> 0
E30: =_xlfn.IFNA(VLOOKUP(C30,'بيانات الآليات '!A:G,4,FALSE()),"") | F30: =_xlfn.IFNA(VLOOKUP(C30,'بيانات الآليات '!A:G,2,FALSE()),"") | H30: =_xlfn.IFNA(VLOOKUP(C30,'بيانات الآليات '!A:G,5,FALSE()),"") | J30: =_xlfn.IFNA(VLOOKUP(I30,Table14543[],2,FALSE()),"") | K30: =_xlfn.IFNA(VLOOKUP(I30,Table14543[],3,FALSE()),"") | L30: =CONCATENATE("",I30,""," ",J30," ",K30) | P30: =N30*O30 -> 0 | R30: =(O30*N30)+Q30 -> 0
... E712: =_xlfn.IFNA(VLOOKUP(C712,'بيانات الآليات '!A:G,4,FALSE()),"") | F712: =_xlfn.IFNA(VLOOKUP(C712,'بيانات الآليات '!A:G,2,FALSE()),"") | H712: =_xlfn.IFNA(VLOOKUP(C712,'بيانات الآليات '!A:G,5,FALSE()),"") | J712: =_xlfn.IFNA(VLOOKUP(I712,Table14543[],2,FALSE()),"") | K712: =_xlfn.IFNA(VLOOKUP(I712,Table14543[],3,FALSE()),"") | L712: =CONCATENATE("",I712,""," ",J712," ",K712) | P712: =N712*O712 -> 0 | R712: =(O712*N712)+Q712 -> 0
R716: =SUM(R2:R715) -> 9750
